Workbook

Sheet Chi tiết bảng NV
A1: DANH SÁCH CHI TIẾT BẢNG NGHIỆP VỤ
A2: STT | B2: Tên bảng | C2: Mô tả | D2: Phân hệ | E2: Loại | F2: Logical Object (Thiết kế)
A3: 1 | B3: COUNTRY | C3: Lưu thông tin mã quốc gia; tên tiếng việt; tên tiếng anh | D3: Danh mục điện tử dùng chung (Q2) | E3: Danh mục | F3: Location
A4: 2 | B4: REGION | C4: Lưu thông tin mã vùng; tên phân hệ; trạng thái (1: active, 0: unactive) | D4: Danh mục điện tử dùng chung (Q2) | E4: Danh mục | F4: Location
A5: 3 | B5: PROVINCE_NEW | C5: Lưu thông tin mã tỉnh/thành phố'; tên tiếng việt; tên tiếng anh | D5: Danh mục điện tử dùng chung (Q2) | E5: Danh mục | F5: Location
A6: 4 | B6: PROVINCE_OLD | C6: Lưu thông tin mã tỉnh/thành phố'; tên tiếng việt; tên tiếng anh | D6: Danh mục điện tử dùng chung (Q2) | E6: Danh mục | F6: Location
A7: 5 | B7: DISTRICT_OLD | C7: Lưu thông tin mã quận/huyện; tên phân hệ; stable id tỉnh/thành phố cũ (tham chiếu province_old.stableid) | D7: Danh mục điện tử dùng chung (Q2) | E7: Danh mục | F7: Location
A8: 6 | B8: WARD_NEW | C8: Lưu thông tin mã phường/xã; tên tiếng việt; tên tiếng anh | D8: Danh mục điện tử dùng chung (Q2) | E8: Danh mục | F8: Location
A9: 7 | B9: WARD_OLD | C9: Lưu thông tin mã phường/xã'; tên tiếng việt; tên tiếng anh | D9: Danh mục điện tử dùng chung (Q2) | E9: Danh mục | F9: Location
A10: 8 | B10: CURRENCY | C10: lưu danh sách danh mục tiền tệ | D10: Danh mục điện tử dùng chung (Q2) | E10: Danh mục | F10: Classification
A11: 9 | B11: DEPARTMENT | C11: lưu danh sách danh mục phòng ban | D11: Danh mục điện tử dùng chung (Q2) | E11: Danh mục | F11: Classification
A12: 10 | B12: ENTERPRISE_TYPE | C12: Danh mục loại: mã phòng ban; tên phòng ban; nhãn hiển thị | D12: Danh mục điện tử dùng chung (Q2) | E12: Danh mục | F12: Classification
A13: 11 | B13: SECURITY_TYPE | C13: Danh mục loại: mã loại chứng khoán (auto: lck-{seq}); tên loại chứng khoán; trạng thái hoạt động (1: đang sử dụng, 0: không sử dụng) | D13: Danh mục điện tử dùng chung (Q2) | E13: Danh mục | F13: Classification
A14: 12 | B14: MARKET | C14: Lưu thông tin mã thị trường; tên thị trường; trạng thái hoạt động (1: đang sử dụng, 0: không sử dụng) | D14: Danh mục điện tử dùng chung (Q2) | E14: Danh mục | F14: Classification
... A89: 87 | B89: CAT_WARD | C89: Danh mục phường/xã | D89: Giám sát CTCK (SCMS) | E89: Danh mục | F89: Location
A90: 88 | B90: ALERT_FINANCIAL_INDICATOR | C90: Chỉ tiêu tài chính cảnh báo | D90: Giám sát CTCK (SCMS) | E90: Nghiệp vụ
A91: 89 | B91: ALERT_INDICATOR | C91: Chỉ tiêu cảnh báo | D91: Giám sát CTCK (SCMS) | E91: Nghiệp vụ
A92: 90 | B92: ALERT_INDICATOR_CONDITION | C92: Điều kiện kích hoạt cảnh báo chỉ tiêu | D92: Giám sát CTCK (SCMS) | E92: Hệ thống
A93: 91 | B93: ALERT_RUN | C93: Lần chạy cảnh báo | D93: Giám sát CTCK (SCMS) | E93: Hệ thống
A94: 92 | B94: AUDITOR | C94: Kiểm toán viên | D94: Giám sát CTCK (SCMS) | E94: Danh mục
A95: 93 | B95: BANK | C95: Thông tin ngân hàng: tên, mã, địa chỉ, trạng thái hoạt động | D95: Giám sát CTCK (SCMS) | E95: Danh mục
A96: 94 | B96: BANK_PERIODIC_REPORT | C96: Báo cáo định kỳ ngân hàng | D96: Giám sát CTCK (SCMS) | E96: Nghiệp vụ
A97: 95 | B97: CUSTODIAN_BANK | C97: Ngân hàng lưu ký | D97: Giám sát CTCK (SCMS) | E97: Danh mục
A98: 96 | B98: DISCLOSURE_NEWS | C98: Tin tức công bố thông tin | D98: Giám sát CTCK (SCMS) | E98: Nghiệp vụ
A99: 97 | B99: DISCLOSURE_NEWS_FILE | C99: Tệp đính kèm tin tức CBTT | D99: Giám sát CTCK (SCMS) | E99: Hệ thống
A100: 98 | B100: DISCLOSURE_REPORT | C100: Báo cáo công bố thông tin | D100: Giám sát CTCK (SCMS) | E100: Nghiệp vụ
A101: 99 | B101: DISCLOSURE_SECURITIES_OFFERING | C101: Thông tin chào bán chứng khoán | D101: Giám sát CTCK (SCMS) | E101: Nghiệp vụ
... A193: 191 | B193: MEMBER_REPORT_HISTORY | C193: Lịch sử báo cáo của đơn vị thành viên | D193: Giám sát CTCK (SCMS) | E193: Lịch sử
A194: 192 | B194: AGENCY_TYPE | C194: Danh mục loại đại lý phân phối | D194: Giám sát CT QLQ & Quỹ ĐT (FMS) | E194: Danh mục | F194: Classification
A195: 193 | B195: BUSINESS | C195: Danh mục ngành nghề kinh doanh | D195: Giám sát CT QLQ & Quỹ ĐT (FMS) | E195: Danh mục | F195: Classification
A196: 194 | B196: BUSINESS_TYPE | C196: Danh mục loại hình kinh doanh | D196: Giám sát CT QLQ & Quỹ ĐT (FMS) | E196: Danh mục | F196: Classification
A197: 195 | B197: COMPANY_TYPE | C197: Danh mục loại hình công ty | D197: Giám sát CT QLQ & Quỹ ĐT (FMS) | E197: Danh mục | F197: Classification
A198: 196 | B198: FUND_TYPE | C198: Danh mục loại quỹ đầu tư | D198: Giám sát CT QLQ & Quỹ ĐT (FMS) | E198: Danh mục | F198: Classification
A199: 197 | B199: LOCATION | C199: Danh sách tỉnh/thành phố | D199: Giám sát CT QLQ & Quỹ ĐT (FMS) | E199: Danh mục | F199: Location
A200: 198 | B200: NATIONAL | C200: Danh sách quốc gia/quốc tịch | D200: Giám sát CT QLQ & Quỹ ĐT (FMS) | E200: Danh mục | F200: Location
A201: 199 | B201: PAR_VALUE | C201: Danh sách mệnh giá cổ phần/chứng chỉ quỹ | D201: Giám sát CT QLQ & Quỹ ĐT (FMS) | E201: Danh mục | F201: Classification
A202: 200 | B202: RELATION | C202: Danh mục mối quan hệ giữa các bên | D202: Giám sát CT QLQ & Quỹ ĐT (FMS) | E202: Danh mục | F202: Classification
A203: 201 | B203: STATUS | C203: Danh mục trạng thái hoạt động | D203: Giám sát CT QLQ & Quỹ ĐT (FMS) | E203: Danh mục | F203: Classification
A204: 202 | B204: STOCKHOLDER_TYPE | C204: Danh mục loại hình nhà đầu tư/cổ đông | D204: Giám sát CT QLQ & Quỹ ĐT (FMS) | E204: Danh mục | F204: Classification
A205: 203 | B205: FUND_TYPE | C205: Danh mục loại quỹ đầu tư | D205: Giám sát CT QLQ & Quỹ ĐT (FMS) | E205: Danh mục | F205: Classification
...

Sheet Chi tiết bảng HT
A1: DANH SÁCH CHI TIẾT BẢNG HỆ THỐNG (461 bảng – để review)
A2: STT | B2: Tên bảng | C2: Mô tả | D2: Nhóm bảng | E2: Phân hệ | F2: Phân loại hệ thống | G2: Ghi chú (review)
A3: 1 | B3: DATABASECHANGELOG | C3: Lưu thông tin người viết changeset; file chứa changeset; thời điểm changeset được chạy | D3: Mô tả chung | E3: Danh mục điện tử dùng chung (Q2) | F3: Migration / Schema version
A4: 2 | B4: DATABASECHANGELOGLOCK | C4: Lưu thông tin trạng thái lock (1: khóa, 0: không khóa); thời điểm lock được cấp; thông tin người log | D4: Mô tả chung | E4: Danh mục điện tử dùng chung (Q2) | F4: Migration / Schema version
A5: 3 | B5: LOG_DATA_CHANGES | C5: Lưu thông tin tên application; client ip; username | D5: Mô tả chung | E5: Danh mục điện tử dùng chung (Q2) | F5: Log / Audit
A6: 4 | B6: AUDIT_FIRM | C6: Công ty kiểm toán | D6: Nhóm bảng AUDIT – Kiểm toán | E6: Giám sát CTCK (SCMS) | F6: Log / Audit
A7: 5 | B7: DIGITAL_CERTIFICATE | C7: Chứng thư số | D7: Nhóm bảng CERT – Chứng thư số | E7: Giám sát CTCK (SCMS) | F7: Chứng thư số / Token
A8: 6 | B8: LNK_FUNCTION_USER | C8: Liên kết chức năng và người dùng | D8: Nhóm bảng LNK – Liên kết & Phân quyền | E8: Giám sát CTCK (SCMS) | F8: Quản lý người dùng
A9: 7 | B9: LNK_FUNCTION_USER_GROUP | C9: Liên kết chức năng và nhóm người dùng | D9: Nhóm bảng LNK – Liên kết & Phân quyền | E9: Giám sát CTCK (SCMS) | F9: Quản lý người dùng
A10: 8 | B10: PERMISSION_DATA | C10: Phân quyền dữ liệu | D10: Nhóm bảng LNK – Liên kết & Phân quyền | E10: Giám sát CTCK (SCMS) | F10: Phân quyền / Vai trò
A11: 9 | B11: PERMISSION_INPUT_REPORT | C11: Phân quyền nhập liệu báo cáo | D11: Nhóm bảng LNK – Liên kết & Phân quyền | E11: Giám sát CTCK (SCMS) | F11: Phân quyền / Vai trò
A12: 10 | B12: PERMISSION_INPUT_REPORT_EVENT | C12: Phân quyền sự kiện nhập liệu báo cáo | D12: Nhóm bảng LNK – Liên kết & Phân quyền | E12: Giám sát CTCK (SCMS) | F12: Phân quyền / Vai trò
A13: 11 | B13: PERMISSION_OUTPUT_REPORT | C13: Phân quyền khai thác báo cáo | D13: Nhóm bảng LNK – Liên kết & Phân quyền | E13: Giám sát CTCK (SCMS) | F13: Phân quyền / Vai trò
A14: 12 | B14: PERMISSION_OUTPUT_REPORT_FORM | C14: Phân quyền biểu mẫu báo cáo khai thác | D14: Nhóm bảng LNK – Liên kết & Phân quyền | E14: Giám sát CTCK (SCMS) | F14: Phân quyền / Vai trò
... A223: 221 | B223: INVESTOR_ACCOUNT_DASHBOARD | C223: Lưu thông tin thời điểm job lấy dữ liệu; tổng số tài khoản; số tài khoản mở | D223: Phân hệ Giám sát giao dịch chứng khoán | E223: Giám sát giao dịch chứng khoán (Q5) | F223: Hệ thống khác
A224: nfnnfsdnnfnewjnf | B224: BUSINESS_DASHBOARD | C224: Lưu thông tin thời điểm job lấy dữ liệu; số lượng sự kiện của tổ chức niêm yết cần phê duyệt; số lượng tổ chức niêm yết | D224: Phân hệ Giám sát giao dịch chứng khoán | E224: Giám sát giao dịch chứng khoán (Q5) | F224: Hệ thống khác
A225: 223 | B225: PERMISSION_GROUP | C225: Lưu thông tin tên nhóm quyền; mô tả | D225: Phân hệ Quản lý rủi ro về thị trường chứng khoán | E225: Quản lý rủi ro TTCK (Q16) | F225: Phân quyền / Vai trò
A226: 224 | B226: PERMISSION_GROUP_USER | C226: Lưu thông tin người dùng được phân quyền (user id); mã người dùng; tên người dùng được phân quyền | D226: Phân hệ Quản lý rủi ro về thị trường chứng khoán | E226: Quản lý rủi ro TTCK (Q16) | F226: Quản lý người dùng
A227: 225 | B227: PERMISSION_GROUP_INDICATOR | C227: Lưu thông tin chỉ tiêu (indicator id) | D227: Phân hệ Quản lý rủi ro về thị trường chứng khoán | E227: Quản lý rủi ro TTCK (Q16) | F227: Phân quyền / Vai trò
A228: 226 | B228: REPORT_PERMISSION_GROUP | C228: Lưu thông tin mã nhóm phân quyền; tên nhóm phân quyền; trạng thái: draft, active, expired, cancelled | D228: Phân hệ Thống kê nội bộ | E228: Thống kê nội bộ (Q15) | F228: Phân quyền / Vai trò
A229: 227 | B229: AUDIT_LOG | C229: Nhật ký: tên đăng nhập; loại thực thể; mô tả hành động | D229: Phân hệ Thống kê nội bộ | E229: Thống kê nội bộ (Q15) | F229: Log / Audit
A230: 228 | B230: USER_PERMISSIONS_GROUP | D230: Phân hệ Thống kê nội bộ | E230: Thống kê nội bộ (Q15) | F230: Quản lý người dùng
A231: 229 | B231: HT_THAM_SO | C231: Lưu các thông tin về tham số hệ thống | D231: Nhóm dữ liệu Quản trị hệ thống | E231: Kết nối trao đổi dữ liệu (Q19) | F231: Quản trị hệ thống
A232: 230 | B232: NHAT_KY_HE_THONG | C232: Lưu các thông tin về nhật ký phân hệ, các thao tác của người dùng trên phân hệ | D232: Nhóm dữ liệu Quản trị hệ thống | E232: Kết nối trao đổi dữ liệu (Q19) | F232: Quản trị hệ thống
A233: 231 | B233: THIET_LAP_LICH | C233: Bảng lưu cấu hình lịch truyền/ nhận dữ liệu giữa UBCKNN và Cục Thuế | D233: Nhóm dữ liệu Quản trị hệ thống | E233: Kết nối trao đổi dữ liệu (Q19) | F233: Job / Scheduler
A234: 232 | B234: DB_LOG | C234: Bảng lưu log truy vấn trên database | D234: Nhóm dữ liệu Quản trị hệ thống | E234: Kết nối trao đổi dữ liệu (Q19) | F234: Log / Audit
A235: 233 | B235: LOGINS | C235: Bảng tài khoản đăng nhập | D235: 2.1.1 Các mô hình quan hệ dữ liệu | E235: IDS – Hệ thống dữ liệu nhận dạng tổ chức | F235: Quản lý người dùng
A236: 234 | B236: USER_AUDIT_LOG | C236: Bảng lưu log người dùng thao tác trên hệ thống | D236: 2.1.1 Các mô hình quan hệ dữ liệu | E236: IDS – Hệ thống dữ liệu nhận dạng tổ chức | F236: Quản lý người dùng
A237: 235 | B237: NOTIFICATIONS | C237: Thông báo trong hệ thống NHNCK: loại thông báo, loại hành động, nội dung, liên kết, người nhận, thời gian gửi/đọc | D237: 2.1.1 Các mô hình quan hệ dữ liệu | E237: IDS – Hệ thống dữ liệu nhận dạng tổ chức | F237: Thông báo hệ thống
A238: 236 | B238: SYS_PARAMETERS | C238: Lưu trữ cấu hình tham số hệ thống | D238: 2.1.1 Các mô hình quan hệ dữ liệu | E238: IDS – Hệ thống dữ liệu nhận dạng tổ chức | F238: Cấu hình / Hạ tầng
A239: 237 | B239: INTG_REPORT_CONFIG | C239: Lưu thông tin cấu hình mẫu báo cáo cần đẩy lên IDS | D239: 2.1.1 Các mô hình quan hệ dữ liệu | E239: IDS – Hệ thống dữ liệu nhận dạng tổ chức | F239: Cấu hình / Hạ tầng
A240: 238 | B240: INTG_SIGNATURE_CONFIG | C240: Cấu hình master cho các lịch trình và chữ ký chứng khoán (HNX, HOSE) | D240: 2.1.1 Các mô hình quan hệ dữ liệu | E240: IDS – Hệ thống dữ liệu nhận dạng tổ chức | F240: Cấu hình / Hạ tầng
A241: 239 | B241: CONTENTITEMINDEX | C241: Orchard Core - chỉ mục chính của tất cả content item (loại, trạng thái publish, chủ sở hữu, ngày, đường dẫn) | D241: Noi dung va cau truc du lieu | E241: Thủ tục hành chính (TTHC) | F241: Platform hạ tầng (TTHC)
A242: 240 | B242: DOCUMENT | C242: Quản lý tài liệu đính kèm hồ sơ | D242: Noi dung va cau truc du lieu | E242: Thủ tục hành chính (TTHC) | F242: Platform hạ tầng (TTHC)
... A463: 461 | B463: TVRP_GA4_CONFIGS | C463: Cấu hình Google Analytics 4 - thông tin đăng nhập GA4 được mã hóa theo từng site | D463: TVRP - Khac | E463: Thủ tục hành chính (TTHC) | F463: Cấu hình / Hạ tầng

Sheet Kế hoạch
A1: PIVOT: LOẠI BẢNG × PHÂN HỆ | I1: Thiết kế bảng | K1: Thiết kế trường + mapping | M1: Lập trình Atomic
A2: Thiết kế Atomic | B2: Danh mục | C2: Nghiệp vụ | D2: Lịch sử | E2: Báo cáo động | F2: Tổng bảng chứa DL nghiệp vụ | G2: Phân loại | H2: Trạng thái | I2: Start | J2: End | K2: Start | L2: End | M2: Start | N2: End
A3: Danh mục điện tử dùng chung (Q2) | B3: =COUNTIFS('Chi tiết bảng NV'!$D$2:$D$1000,'Kế hoạch'!A3,'Chi tiết bảng NV'!$E$2:$E$1000,'Kế hoạch'!$B$2) -> 65 | C3: =COUNTIFS('Chi tiết bảng NV'!$D$2:$D$1000,'Kế hoạch'!A3,'Chi tiết bảng NV'!$E$2:$E$1000,'Kế hoạch'!$C$2) -> 0 | D3: =COUNTIFS('Chi tiết bảng NV'!$D$2:$D$1000,'Kế hoạch'!A3,'Chi tiết bảng NV'!$E$2:$E$1000,'Kế hoạch'!$D$2) -> 0 | E3: =COUNTIFS('Chi tiết bảng NV'!$D$2:$D$1000,'Kế hoạch'!A3,'Chi tiết bảng NV'!$E$2:$E$1000,$E$2) -> 0 | F3: =SUM(B3:E3) -> 65 | G3: Chỉ thiết kế ATM, Không lên DTM | H3: Đã thiết kế | I3: Done | J3: Done | K3: 46203 | L3: 46203 | M3: =L3+1 -> 46204 | N3: =M3+3 -> 46207
A4: Giám sát CTCK (SCMS) | B4: =COUNTIFS('Chi tiết bảng NV'!$D$2:$D$1000,'Kế hoạch'!A4,'Chi tiết bảng NV'!$E$2:$E$1000,'Kế hoạch'!$B$2) -> 29 | C4: =COUNTIFS('Chi tiết bảng NV'!$D$2:$D$1000,'Kế hoạch'!A4,'Chi tiết bảng NV'!$E$2:$E$1000,'Kế hoạch'!$C$2) -> 57 | D4: =COUNTIFS('Chi tiết bảng NV'!$D$2:$D$1000,'Kế hoạch'!A4,'Chi tiết bảng NV'!$E$2:$E$1000,'Kế hoạch'!$D$2) -> 12 | E4: =COUNTIFS('Chi tiết bảng NV'!$D$2:$D$1000,'Kế hoạch'!A4,'Chi tiết bảng NV'!$E$2:$E$1000,$E$2) -> 19 | F4: =SUM(B4:E4) -> 117 | H4: Xong thiết kế mức bảng | I4: Done | J4: Done | K4: 46203 | L4: 46204 | M4: =L4+1 -> 46205 | N4: =M4+3 -> 46208
A5: Giám sát CT QLQ & Quỹ ĐT (FMS) | B5: =COUNTIFS('Chi tiết bảng NV'!$D$2:$D$1000,'Kế hoạch'!A5,'Chi tiết bảng NV'!$E$2:$E$1000,'Kế hoạch'!$B$2) -> 13 | C5: =COUNTIFS('Chi tiết bảng NV'!$D$2:$D$1000,'Kế hoạch'!A5,'Chi tiết bảng NV'!$E$2:$E$1000,'Kế hoạch'!$C$2) -> 59 | D5: =COUNTIFS('Chi tiết bảng NV'!$D$2:$D$1000,'Kế hoạch'!A5,'Chi tiết bảng NV'!$E$2:$E$1000,'Kế hoạch'!$D$2) -> 28 | E5: =COUNTIFS('Chi tiết bảng NV'!$D$2:$D$1000,'Kế hoạch'!A5,'Chi tiết bảng NV'!$E$2:$E$1000,$E$2) -> 10 | F5: =SUM(B5:E5) -> 110 | I5: 46203 | J5: 46203 | K5: 46205 | L5: =J5+3 -> 46206 | M5: =L5+1 -> 46207 | N5: =M5+3 -> 46210
A6: Giám sát NĐT nước ngoài (FIMS) | B6: =COUNTIFS('Chi tiết bảng NV'!$D$2:$D$1000,'Kế hoạch'!A6,'Chi tiết bảng NV'!$E$2:$E$1000,'Kế hoạch'!$B$2) -> 24 | C6: =COUNTIFS('Chi tiết bảng NV'!$D$2:$D$1000,'Kế hoạch'!A6,'Chi tiết bảng NV'!$E$2:$E$1000,'Kế hoạch'!$C$2) -> 26 | D6: =COUNTIFS('Chi tiết bảng NV'!$D$2:$D$1000,'Kế hoạch'!A6,'Chi tiết bảng NV'!$E$2:$E$1000,'Kế hoạch'!$D$2) -> 10 | E6: =COUNTIFS('Chi tiết bảng NV'!$D$2:$D$1000,'Kế hoạch'!A6,'Chi tiết bảng NV'!$E$2:$E$1000,$E$2) -> 8 | F6: =SUM(B6:E6) -> 68 | I6: 46203 | J6: 46203 | K6: 46205 | L6: =J6+3 -> 46206 | M6: =L6+1 -> 46207 | N6: =M6+3 -> 46210
A7: Người hành nghề chứng khoán (NHNCK) | B7: =COUNTIFS('Chi tiết bảng NV'!$D$2:$D$1000,'Kế hoạch'!A7,'Chi tiết bảng NV'!$E$2:$E$1000,'Kế hoạch'!$B$2) -> 13 | C7: =COUNTIFS('Chi tiết bảng NV'!$D$2:$D$1000,'Kế hoạch'!A7,'Chi tiết bảng NV'!$E$2:$E$1000,'Kế hoạch'!$C$2) -> 48 | D7: =COUNTIFS('Chi tiết bảng NV'!$D$2:$D$1000,'Kế hoạch'!A7,'Chi tiết bảng NV'!$E$2:$E$1000,'Kế hoạch'!$D$2) -> 5 | E7: =COUNTIFS('Chi tiết bảng NV'!$D$2:$D$1000,'Kế hoạch'!A7,'Chi tiết bảng NV'!$E$2:$E$1000,$E$2) -> 0 | F7: =SUM(B7:E7) -> 66 | H7: Đã thiết kế | I7: Done | J7: Done | K7: Done | L7: Done
A8: Thanh tra chứng khoán | B8: =COUNTIFS('Chi tiết bảng NV'!$D$2:$D$1000,'Kế hoạch'!A8,'Chi tiết bảng NV'!$E$2:$E$1000,'Kế hoạch'!$B$2) -> 0 | C8: =COUNTIFS('Chi tiết bảng NV'!$D$2:$D$1000,'Kế hoạch'!A8,'Chi tiết bảng NV'!$E$2:$E$1000,'Kế hoạch'!$C$2) -> 54 | D8: =COUNTIFS('Chi tiết bảng NV'!$D$2:$D$1000,'Kế hoạch'!A8,'Chi tiết bảng NV'!$E$2:$E$1000,'Kế hoạch'!$D$2) -> 2 | E8: =COUNTIFS('Chi tiết bảng NV'!$D$2:$D$1000,'Kế hoạch'!A8,'Chi tiết bảng NV'!$E$2:$E$1000,$E$2) -> 0 | F8: =SUM(B8:E8) -> 56 | H8: Đã thiết kế | I8: Done | J8: Done | K8: 46203 | L8: 46203
A9: Giám sát giao dịch chứng khoán (Q5) | B9: =COUNTIFS('Chi tiết bảng NV'!$D$2:$D$1000,'Kế hoạch'!A9,'Chi tiết bảng NV'!$E$2:$E$1000,'Kế hoạch'!$B$2) -> 2 | C9: =COUNTIFS('Chi tiết bảng NV'!$D$2:$D$1000,'Kế hoạch'!A9,'Chi tiết bảng NV'!$E$2:$E$1000,'Kế hoạch'!$C$2) -> 15 | D9: =COUNTIFS('Chi tiết bảng NV'!$D$2:$D$1000,'Kế hoạch'!A9,'Chi tiết bảng NV'!$E$2:$E$1000,'Kế hoạch'!$D$2) -> 7 | E9: =COUNTIFS('Chi tiết bảng NV'!$D$2:$D$1000,'Kế hoạch'!A9,'Chi tiết bảng NV'!$E$2:$E$1000,$E$2) -> 7 | F9: =SUM(B9:E9) -> 31 | G9: Chỉ thiết kế ATM, Không lên DTM | I9: 46203 | J9: 46203 | K9: 46209 | L9: 46210 | M9: =L9+1 -> 46211 | N9: =M9+3 -> 46214
A10: Giám sát giao dịch trực tuyến (Q3) | B10: =COUNTIFS('Chi tiết bảng NV'!$D$2:$D$1000,'Kế hoạch'!A10,'Chi tiết bảng NV'!$E$2:$E$1000,'Kế hoạch'!$B$2) -> 1 | C10: =COUNTIFS('Chi tiết bảng NV'!$D$2:$D$1000,'Kế hoạch'!A10,'Chi tiết bảng NV'!$E$2:$E$1000,'Kế hoạch'!$C$2) -> 7 | D10: =COUNTIFS('Chi tiết bảng NV'!$D$2:$D$1000,'Kế hoạch'!A10,'Chi tiết bảng NV'!$E$2:$E$1000,'Kế hoạch'!$D$2) -> 1 | E10: =COUNTIFS('Chi tiết bảng NV'!$D$2:$D$1000,'Kế hoạch'!A10,'Chi tiết bảng NV'!$E$2:$E$1000,$E$2) -> 0 | F10: =SUM(B10:E10) -> 9 | G10: Chỉ thiết kế ATM, Không lên DTM | I10: 46203 | J10: 46203 | K10: 46209 | L10: 46210 | M10: =L10+1 -> 46211 | N10: =M10+3 -> 46214
A11: Quản lý rủi ro TTCK (Q16) | B11: =COUNTIFS('Chi tiết bảng NV'!$D$2:$D$1000,'Kế hoạch'!A11,'Chi tiết bảng NV'!$E$2:$E$1000,'Kế hoạch'!$B$2) -> 4 | C11: =COUNTIFS('Chi tiết bảng NV'!$D$2:$D$1000,'Kế hoạch'!A11,'Chi tiết bảng NV'!$E$2:$E$1000,'Kế hoạch'!$C$2) -> 0 | D11: =COUNTIFS('Chi tiết bảng NV'!$D$2:$D$1000,'Kế hoạch'!A11,'Chi tiết bảng NV'!$E$2:$E$1000,'Kế hoạch'!$D$2) -> 2 | E11: =COUNTIFS('Chi tiết bảng NV'!$D$2:$D$1000,'Kế hoạch'!A11,'Chi tiết bảng NV'!$E$2:$E$1000,$E$2) -> 10 | F11: =SUM(B11:E11) -> 16 | G11: Dữ liệu chỉ tiêu, không thiết kế | I11: x | J11: x | K11: x | L11: x
A12: Thống kê nội bộ (Q15) | B12: =COUNTIFS('Chi tiết bảng NV'!$D$2:$D$1000,'Kế hoạch'!A12,'Chi tiết bảng NV'!$E$2:$E$1000,'Kế hoạch'!$B$2) -> 0 | C12: =COUNTIFS('Chi tiết bảng NV'!$D$2:$D$1000,'Kế hoạch'!A12,'Chi tiết bảng NV'!$E$2:$E$1000,'Kế hoạch'!$C$2) -> 0 | D12: =COUNTIFS('Chi tiết bảng NV'!$D$2:$D$1000,'Kế hoạch'!A12,'Chi tiết bảng NV'!$E$2:$E$1000,'Kế hoạch'!$D$2) -> 0 | E12: =COUNTIFS('Chi tiết bảng NV'!$D$2:$D$1000,'Kế hoạch'!A12,'Chi tiết bảng NV'!$E$2:$E$1000,$E$2) -> 17 | F12: =SUM(B12:E12) -> 17 | G12: Dữ liệu chỉ tiêu, không thiết kế | I12: x | J12: x | K12: x | L12: x
A13: Kết nối trao đổi dữ liệu (Q19) | B13: =COUNTIFS('Chi tiết bảng NV'!$D$2:$D$1000,'Kế hoạch'!A13,'Chi tiết bảng NV'!$E$2:$E$1000,'Kế hoạch'!$B$2) -> 0 | C13: =COUNTIFS('Chi tiết bảng NV'!$D$2:$D$1000,'Kế hoạch'!A13,'Chi tiết bảng NV'!$E$2:$E$1000,'Kế hoạch'!$C$2) -> 16 | D13: =COUNTIFS('Chi tiết bảng NV'!$D$2:$D$1000,'Kế hoạch'!A13,'Chi tiết bảng NV'!$E$2:$E$1000,'Kế hoạch'!$D$2) -> 0 | E13: =COUNTIFS('Chi tiết bảng NV'!$D$2:$D$1000,'Kế hoạch'!A13,'Chi tiết bảng NV'!$E$2:$E$1000,$E$2) -> 0 | F13: =SUM(B13:E13) -> 16 | G13: Chỉ thiết kế ATM, Không lên DTM | I13: 46203 | J13: 46203 | K13: 46209 | L13: 46210 | M13: =L13+1 -> 46211 | N13: =M13+3 -> 46214
A14: IDS | B14: =COUNTIFS('Chi tiết bảng NV'!$D$2:$D$1000,'Kế hoạch'!A14,'Chi tiết bảng NV'!$E$2:$E$1000,'Kế hoạch'!$B$2) -> 8 | C14: =COUNTIFS('Chi tiết bảng NV'!$D$2:$D$1000,'Kế hoạch'!A14,'Chi tiết bảng NV'!$E$2:$E$1000,'Kế hoạch'!$C$2) -> 48 | D14: =COUNTIFS('Chi tiết bảng NV'!$D$2:$D$1000,'Kế hoạch'!A14,'Chi tiết bảng NV'!$E$2:$E$1000,'Kế hoạch'!$D$2) -> 7 | E14: =COUNTIFS('Chi tiết bảng NV'!$D$2:$D$1000,'Kế hoạch'!A14,'Chi tiết bảng NV'!$E$2:$E$1000,$E$2) -> 11 | F14: =SUM(B14:E14) -> 74 | H14: Xong thiết kế mức bảng | I14: Done | J14: Done | K14: 46203 | L14: 46204 | M14: =L14+1 -> 46205 | N14: =M14+3 -> 46208
A15: Thủ tục hành chính (TTHC) | B15: =COUNTIFS('Chi tiết bảng NV'!$D$2:$D$1000,'Kế hoạch'!A15,'Chi tiết bảng NV'!$E$2:$E$1000,'Kế hoạch'!$B$2) -> 0 | C15: =COUNTIFS('Chi tiết bảng NV'!$D$2:$D$1000,'Kế hoạch'!A15,'Chi tiết bảng NV'!$E$2:$E$1000,'Kế hoạch'!$C$2) -> 0 | D15: =COUNTIFS('Chi tiết bảng NV'!$D$2:$D$1000,'Kế hoạch'!A15,'Chi tiết bảng NV'!$E$2:$E$1000,'Kế hoạch'!$D$2) -> 0 | E15: =COUNTIFS('Chi tiết bảng NV'!$D$2:$D$1000,'Kế hoạch'!A15,'Chi tiết bảng NV'!$E$2:$E$1000,$E$2) -> 0 | F15: =SUM(B15:E15) -> 0 | G15: Chỉ thiết kế ATM, Không lên DTM | I15: 46203 | J15: 46203 | K15: 46209 | L15: 46210 | M15: =L15+1 -> 46211 | N15: =M15+3 -> 46214
A16: Sổ lệnh, DL Thị trường, VSDC | G16: Không thiết kế, đẩy 1:1 hoặc chỉ tiêu động | I16: 46202 | J16: 46202 | K16: 46202 | L16: 46202 | M16: =L16+1 -> 46203 | N16: =M16+3 -> 46206
A17: TỔNG | B17: =SUM(B3:B15) -> 159 | C17: =SUM(C3:C15) -> 330 | D17: =SUM(D3:D15) -> 74 | E17: =SUM(E3:E15) -> 82 | F17: =SUM(F3:F15) -> 645
B19: Thiết kế bảng | D19: Thiết kế trường + mapping
A20: Thiết kế Datamart | B20: Start | C20: End | D20: Start | E20: End
A21: Giám sát CTCK (SCMS) | B21: =E22+2 -> 46216 | C21: =B21 -> 46216 | D21: =C21+1 -> 46217 | E21: =D21 -> 46217
A22: Giám sát CT QLQ & Quỹ ĐT (FMS) | B22: =B23+1 -> 46213 | C22: =B22 -> 46213 | D22: =C22+1 -> 46214 | E22: =D22 -> 46214
A23: Giám sát NĐT nước ngoài (FIMS) | B23: =D26+1 -> 46212 | C23: =B23 -> 46212 | D23: =C23 -> 46212 | E23: =D23 -> 46212
A24: Người hành nghề chứng khoán (NHNCK) | B24: Done | C24: Done | D24: Done | E24: Done
A25: Thanh tra chứng khoán | B25: =L8+1 -> 46204 | C25: =B25 -> 46204 | D25: 46204 | E25: 46204
A26: Giám sát giao dịch chứng khoán (Q5) | B26: =B29+1 -> 46210 | C26: =B26 -> 46210 | D26: =C26+1 -> 46211 | E26: =D26 -> 46211
A27: Quản lý rủi ro TTCK (Q16) | B27: =E21+1 -> 46218 | C27: =B27 -> 46218 | D27: =C27+1 -> 46219 | E27: =D27 -> 46219
A28: Thống kê nội bộ (Q15) | B28: =E31+1 -> 46224 | C28: =B28 -> 46224 | D28: =C28+1 -> 46225 | E28: =D28 -> 46225
A29: Quản lý chào bán | B29: =E30+3 -> 46209 | C29: =B29 -> 46209 | D29: =C29 -> 46209 | E29: =D29 -> 46209
A30: Quản lý công ty đại chúng | B30: =L14+1 -> 46205 | C30: =B30 -> 46205 | D30: =C30+1 -> 46206 | E30: =D30 -> 46206
A31: Văn phòng - Tổng hợp | B31: =D27+1 -> 46220 | C31: =B31 -> 46220 | D31: 46223 | E31: =D31 -> 46223
